Workbook

Sheet Persons
A1: WissKI ID | B1: Identifier | C1: Service | D1: Descriptive name | E1: Name in source (orig) | F1: Name in source (transl) | G1: Gender assignment | H1: Ethnicity | I1: Social role (C2) | J1: Legal role (C12) | K1: Language skill | L1: Religion | M1: Authority | N1: Authority group | O1: Based on | P1: Source text/publication | Q1: Source text/reference | R1: Source text/excerpt | S1: ID string
A2: https://r11.eu/rdf/resource/6f21cc33-baa9-417f-bd99-1cfd796e5ebc | B2: Aaron 101 | C2: https://pbw2016.kdl.kcl.ac.uk/ | D2: Aaron, brother of Alousianos | S2: =_xlfn.CONCAT(B2, " / ", D2) -> Aaron 101 / Aaron, brother of Alousianos
A3: https://r11.eu/rdf/resource/37ade4c7-baf2-4bec-b978-9220da8a0c0a | B3: Ioannes 110 | C3: https://pbw2016.kdl.kcl.ac.uk/ | D3: Ioannes Skylitzes, historian | S3: =_xlfn.CONCAT(B3, " / ", D3) -> Ioannes 110 / Ioannes Skylitzes, historian
A4: https://r11.eu/rdf/resource/7231f2c2-e72b-4cd6-abe4-a96c96c18a0b | B4: Ioannes 6007 | C4: https://pbw2016.kdl.kcl.ac.uk/ | D4: Ioannes Zonaras | S4: =_xlfn.CONCAT(B4, " / ", D4) -> Ioannes 6007 / Ioannes Zonaras
A5: https://r11.eu/rdf/resource/3dee6940-7654-4203-abe6-3002701f4978 | B5: Aristakes 101 | C5: https://pbw2016.kdl.kcl.ac.uk/ | D5: Aristakes Lastivertc'i / of Lastivert, Armenian historian | S5: =_xlfn.CONCAT(B5, " / ", D5) -> Aristakes 101 / Aristakes Lastivertc'i / of Lastivert, Armenian historian
A6: https://r11.eu/rdf/resource/3730d2a8-0994-47d8-b122-dedb83652e00 | B6: Eustathios 105 | C6: https://pbw2016.kdl.kcl.ac.uk/ | D6: Eustathios Boilas | S6: =_xlfn.CONCAT(B6, " / ", D6) -> Eustathios 105 / Eustathios Boilas
A7: https://r11.eu/rdf/resource/0f7afd6a-cdd8-4a6e-b7bf-19bff9fd2c82 | B7: Alousianos 101 | C7: https://pbw2016.kdl.kcl.ac.uk/ | D7: Alousianos, son of Ioannes/John Vladislav | S7: =_xlfn.CONCAT(B7, " / ", D7) -> Alousianos 101 / Alousianos, son of Ioannes/John Vladislav
A8: https://r11.eu/rdf/resource/308b9a54-9f9d-42a3-81e1-bf435a40f664 | B8: Vladislav 101 | C8: https://pbw2016.kdl.kcl.ac.uk/ | D8: John Vladislav, ruler of Bulgaria | S8: =_xlfn.CONCAT(B8, " / ", D8) -> Vladislav 101 / John Vladislav, ruler of Bulgaria
A9: https://r11.eu/rdf/resource/90f6f7c6-10a3-404d-92d2-e1ba435ef3b8 | B9: Prousianos 101 | C9: https://pbw2016.kdl.kcl.ac.uk/ | D9: Prousianos, son of John Vladislav of Bulgaria | S9: =_xlfn.CONCAT(B9, " / ", D9) -> Prousianos 101 / Prousianos, son of John Vladislav of Bulgaria
A10: https://r11.eu/rdf/resource/35235889-599a-4f10-aa14-bae77a13c5e8 | B10: Aikaterine 101 | C10: https://pbw2016.kdl.kcl.ac.uk/ | D10: Aikaterine of Bulgaria, wife of Isaakios I Komnenos | S10: =_xlfn.CONCAT(B10, " / ", D10) -> Aikaterine 101 / Aikaterine of Bulgaria, wife of Isaakios I Komnenos
A11: https://r11.eu/rdf/resource/cfb62a1d-e5a5-4741-a3a3-327ae2a937d2 | B11: Theodoros 173 | C11: https://pbw2016.kdl.kcl.ac.uk/ | D11: Theodoros, governor of Taron, son of Aaron | S11: =_xlfn.CONCAT(B11, " / ", D11) -> Theodoros 173 / Theodoros, governor of Taron, son of Aaron
A12: https://r11.eu/rdf/resource/823d2106-62ab-4715-a407-d972c998ae1d | B12: Tatranes 101 | C12: https://pbw2016.kdl.kcl.ac.uk/ | D12: Tatranes, Pecheneg deserter to Alexios I | S12: =_xlfn.CONCAT(B12, " / ", D12) -> Tatranes 101 / Tatranes, Pecheneg deserter to Alexios I
A13: https://r11.eu/rdf/resource/a4705735-c9ee-4b64-acad-6b71dc07e6dd | B13: Anna 62 | C13: https://pbw2016.kdl.kcl.ac.uk/ | D13: Anna Komnene, daughter of Alexios I and historian | S13: =_xlfn.CONCAT(B13, " / ", D13) -> Anna 62 / Anna Komnene, daughter of Alexios I and historian
... A193: https://r11.eu/rdf/resource/d90ed912-779d-4f91-b6a9-e7ebd795154b | B193: Andronikos 62 | C193: https://pbw2016.kdl.kcl.ac.uk/ | D193: Andronikos Doukas, brother of Michael VII | S193: =_xlfn.CONCAT(B193, " / ", D193) -> Andronikos 62 / Andronikos Doukas, brother of Michael VII
A194: https://r11.eu/rdf/resource/e7265cc7-4659-47c5-871b-2b8f62024b95 | B194: Konstantios 61 | C194: https://pbw2016.kdl.kcl.ac.uk/ | D194: Konstantios Doukas, brother of Michael VII | S194: =_xlfn.CONCAT(B194," / ",D194) -> Konstantios 61 / Konstantios Doukas, brother of Michael VII
A195: https://r11.eu/rdf/resource/e25a4a6c-a2bc-400b-8f34-450a4798e105 | B195: Michael 121 | C195: https://pbw2016.kdl.kcl.ac.uk/ | D195: Michael Doukas, brother of Eirene Doukaina | S195: =_xlfn.CONCAT(B195," / ",D195) -> Michael 121 / Michael Doukas, brother of Eirene Doukaina
A196: https://r11.eu/rdf/resource/3cdc803e-2edc-4039-b78d-a072dada8149 | B196: Konstantinos 61 | C196: https://pbw2016.kdl.kcl.ac.uk/ | D196: Konstantinos Doukas, son of Kaisar Ioannes | S196: =_xlfn.CONCAT(B196," / ",D196) -> Konstantinos 61 / Konstantinos Doukas, son of Kaisar Ioannes
A197: https://r11.eu/rdf/resource/e2b7aa9a-e6d6-4e45-9327-72ed0e127a5d | B197: Maria 62 | C197: https://pbw2016.kdl.kcl.ac.uk/ | D197: Maria of Bulgaria, wife of Andronikos Doukas | S197: =_xlfn.CONCAT(B197," / ",D197) -> Maria 62 / Maria of Bulgaria, wife of Andronikos Doukas
A198: https://r11.eu/rdf/resource/ae1e9870-d548-47a7-aa48-da4016e3b0fc | B198: Anna 63 | C198: https://pbw2016.kdl.kcl.ac.uk/ | D198: Anna Doukaina, sister of Eirene Doukaina and wife of Georgios Palaiologos | S198: =_xlfn.CONCAT(B198," / ",D198) -> Anna 63 / Anna Doukaina, sister of Eirene Doukaina and wife of Georgios Palaiologos
A199: https://r11.eu/rdf/resource/7da8d452-e91d-4180-83f7-611f4505d743 | B199: Theodora 5001 | C199: https://pbw2016.kdl.kcl.ac.uk/ | D199: Theodora, sister of Eirene Doukaina | S199: =_xlfn.CONCAT(B199," / ",D199) -> Theodora 5001 / Theodora, sister of Eirene Doukaina
A200: https://r11.eu/rdf/resource/267571d2-9f5a-4863-a9b2-514200c83038 | B200: Eirene 20117 | C200: https://pbw2016.kdl.kcl.ac.uk/ | D200: Eirene Pegonitissa, wife of Ioannes the kaisar | S200: =_xlfn.CONCAT(B200," / ",D200) -> Eirene 20117 / Eirene Pegonitissa, wife of Ioannes the kaisar
A201: https://r11.eu/rdf/resource/2df16e85-b7c6-46b0-b003-7c3a21321a87 | B201: Andronikos 2102 | C201: https://pbw2016.kdl.kcl.ac.uk/ | D201: Andronikos Doukas, father of kaisar Ioannes Doukas | S201: =_xlfn.CONCAT(B201," / ",D201) -> Andronikos 2102 / Andronikos Doukas, father of kaisar Ioannes Doukas
A202: https://r11.eu/rdf/resource/0e6dca10-7f56-4685-a4f5-81508fd1322f | B202: Eustathios 20147 | C202: https://pbw2016.kdl.kcl.ac.uk/ | D202: Eustathios, metropolitan of Thessalonike | S202: =_xlfn.CONCAT(B202," / ",D202) -> Eustathios 20147 / Eustathios, metropolitan of Thessalonike
A203: https://r11.eu/rdf/resource/01eac7db-b871-4344-97ac-8cd94522bf02 | B203: Konstantinos 10 | C203: https://pbw2016.kdl.kcl.ac.uk/ | D203: Emperor Konstantinos X Doukas | S203: =_xlfn.CONCAT(B203," / ",D203) -> Konstantinos 10 / Emperor Konstantinos X Doukas
A204: https://r11.eu/rdf/resource/73aedb3b-e80c-4165-add8-371ca549009c | B204: Eudokia 1 | C204: https://pbw2016.kdl.kcl.ac.uk/ | D204: Empress Eudokia Makrembolitissa | S204: =_xlfn.CONCAT(B204," / ",D204) -> Eudokia 1 / Empress Eudokia Makrembolitissa
A205: https://r11.eu/rdf/resource/526e6f40-2894-4975-a749-5fca39b3f047 | B205: Romanos 4 | C205: https://pbw2016.kdl.kcl.ac.uk/ | D205: Emperor Romanos IV Diogenes | S205: =_xlfn.CONCAT(B205," / ",D205) -> Romanos 4 / Emperor Romanos IV Diogenes
... A1025: https://r11.eu/rdf/resource/f5652096-4109-403c-a711-4b04b6952b73 | B1025: Maria 169 | C1025: https://pbw2016.kdl.kcl.ac.uk/ | D1025: Maria (?), wife of Manuel Komnenos Erotikos | S1025: =_xlfn.CONCAT(B1025," / ",D1025) -> Maria 169 / Maria (?), wife of Manuel Komnenos Erotikos
A1026: https://r11.eu/rdf/resource/f5404d43-c47b-46dc-8ea8-cfd9f0d074fd | B1026: Anonyma 5004 | C1026: https://pbw2016.kdl.kcl.ac.uk/ | D1026: daughter of Manuel Komnenos Erotikos, wife of Michael Dokeianos (?) | S1026: =_xlfn.CONCAT(B1026, " / ", D1026) -> Anonyma 5004 / daughter of Manuel Komnenos Erotikos, wife of Michael Dokeianos (?)
A1027: https://r11.eu/rdf/resource/940e7fe9-6842-433f-a0f0-54efe9832621 | B1027: Barkyaruq 101 | C1027: https://pbw2016.kdl.kcl.ac.uk/ | D1027: Barkyaruq, Seljuq sultan | S1027: =_xlfn.CONCAT(B1027, " / ", D1027) -> Barkyaruq 101 / Barkyaruq, Seljuq sultan
A1028: https://r11.eu/rdf/resource/6a250e11-7116-4668-8056-eccb6b70ebcd | B1028: Malik-Shah 51 | C1028: https://pbw2016.kdl.kcl.ac.uk/ | D1028: Malik-Shah, Seljuk sultan | S1028: =_xlfn.CONCAT(B1028, " / ", D1028) -> Malik-Shah 51 / Malik-Shah, Seljuk sultan
A1029: https://r11.eu/rdf/resource/146017c2-72b6-4d42-8447-9392cecb9307 | B1029: Anonyma 271 | C1029: https://pbw2016.kdl.kcl.ac.uk/ | D1029: freed concubine of sultan Malik-Shah, mother of sultans Muhammad and Sanjar | S1029: =_xlfn.CONCAT(B1029, " / ", D1029) -> Anonyma 271 / freed concubine of sultan Malik-Shah, mother of sultans Muhammad and Sanjar
A1030: https://r11.eu/rdf/resource/e56b3cfd-7b15-4ad4-b52b-9704975a378b | B1030: Muhammad 104 | C1030: https://pbw2016.kdl.kcl.ac.uk/ | D1030: Muhammad ibn Malik-Shah, Seljuq sultan | S1030: =_xlfn.CONCAT(B1030, " / ", D1030) -> Muhammad 104 / Muhammad ibn Malik-Shah, Seljuq sultan
A1031: https://r11.eu/rdf/resource/be22579c-dc0f-4c37-a086-d0043519f865 | B1031: Mawdud 101 | C1031: https://pbw2016.kdl.kcl.ac.uk/ | D1031: Mawdud ibn Isma'il, ruler of part of Azerbayjan | S1031: =_xlfn.CONCAT(B1031, " / ", D1031) -> Mawdud 101 / Mawdud ibn Isma'il, ruler of part of Azerbayjan
A1032: https://r11.eu/rdf/resource/10dc7378-0fa2-472f-93b3-efb63742b6ff | B1032: Ioannes 64 | C1032: https://pbw2016.kdl.kcl.ac.uk/ | D1032: Ioannes the protovestiarios | S1032: =_xlfn.CONCAT(B1032, " / ", D1032) -> Ioannes 64 / Ioannes the protovestiarios
A1033: https://r11.eu/rdf/resource/e2c6794d-f5df-4b66-8805-139a6bde44d9 | B1033: Abu Usama 101 | C1033: https://pbw2016.kdl.kcl.ac.uk/ | D1033: Abu Usama, the cadi of Aleppo | S1033: =_xlfn.CONCAT(B1033, " / ", D1033) -> Abu Usama 101 / Abu Usama, the cadi of Aleppo
A1034: https://r11.eu/rdf/resource/b44432cd-23df-4b42-ac07-899386c87ecc | B1034: Ioannes 66 | C1034: https://pbw2016.kdl.kcl.ac.uk/ | D1034: Ioannes Italos | S1034: =_xlfn.CONCAT(B1034, " / ", D1034) -> Ioannes 66 / Ioannes Italos
A1035: https://r11.eu/rdf/resource/d08f68bc-9180-4026-b7d6-27c5ff000745 | B1035: Niketas 104 | C1035: https://pbw2016.kdl.kcl.ac.uk/ | D1035: Niketas, brother of Michael IV | S1035: =_xlfn.CONCAT(B1035, " / ", D1035) -> Niketas 104 / Niketas, brother of Michael IV
A1036: https://r11.eu/rdf/resource/f8f366b0-2274-4683-a5ca-950f00319146 | B1036: Konstantinos 64 | C1036: https://pbw2016.kdl.kcl.ac.uk/ | D1036: Konstantinos, brother of Michael IV | S1036: =_xlfn.CONCAT(B1036, " / ", D1036) -> Konstantinos 64 / Konstantinos, brother of Michael IV
A1037: https://r11.eu/rdf/resource/a96538c3-da8c-4f2b-a55e-0976e61511c2 | B1037: Maria 104 | C1037: https://pbw2016.kdl.kcl.ac.uk/ | D1037: Maria, sister of Michael IV, mother of Michael V | S1037: =_xlfn.CONCAT(B1037, " / ", D1037) -> Maria 104 / Maria, sister of Michael IV, mother of Michael V
... A1089: https://r11.eu/rdf/resource/e327693f-b666-41c1-a6a3-188d8d731039 | B1089: Ioannes 154 | C1089: https://pbw2016.kdl.kcl.ac.uk/ | D1089: Ioannes, tax-payer at chorion of Dobrobikeia | S1089: =_xlfn.CONCAT(B1089, " / ", D1089) -> Ioannes 154 / Ioannes, tax-payer at chorion of Dobrobikeia
...

Sheet Author groups
A1: WissKI ID | B1: Group identifier | C1: Group member
A2: https://r11.eu/rdf/resource/f13bc456-2d72-449a-9595-5acbdf8a4ba4 | B2: Athanasios, hegoumenos of Bouleuteria on Athos; Theodosios, monk and presbyter on Athos | C2: Athanasios 104 / Athanasios, hegoumenos of Bouleuteria on Athos
A3: https://r11.eu/rdf/resource/f13bc456-2d72-449a-9595-5acbdf8a4ba4 | B3: Athanasios, hegoumenos of Bouleuteria on Athos; Theodosios, monk and presbyter on Athos | C3: Theodosios 113 / Theodosios, monk and presbyter on Athos
A4: https://r11.eu/rdf/resource/9754a82b-f2bd-42ec-80e8-bef54e40def9 | B4: Athanasios, hegoumenos of Vatopedi on Athos; Georgios III Hagiorites/Mt'ac'mindeli, hegoumenos of Iveron; Ioannes, hegoumenos of Zygos on Athos; Neophytos, hegoumenos of Lavra on Athos; Theophylaktos, protos of Mount Athos | C4: Athanasios 102 / Athanasios, hegoumenos of Vatopedi on Athos
A5: https://r11.eu/rdf/resource/9754a82b-f2bd-42ec-80e8-bef54e40def9 | B5: Athanasios, hegoumenos of Vatopedi on Athos; Georgios III Hagiorites/Mt'ac'mindeli, hegoumenos of Iveron; Ioannes, hegoumenos of Zygos on Athos; Neophytos, hegoumenos of Lavra on Athos; Theophylaktos, protos of Mount Athos | C5: Georgios 132 / Georgios III Hagiorites/Mt'ac'mindeli, hegoumenos of Iveron
A6: https://r11.eu/rdf/resource/92acb860-00df-4ddb-b69f-7c8cc4a7e776 | B6: Athanasios, hegoumenos of Vatopedi on Athos; Georgios III Hagiorites/Mt'ac'mindeli, hegoumenos of Iveron; Ioannes, hegoumenos of Zygos on Athos; Neophytos, hegoumenos of Lavra on Athos; Theophylaktos, protos of Mount Athos | C6: Ioannes 158 / Ioannes, hegoumenos of Zygos on Athos
A7: https://r11.eu/rdf/resource/92acb860-00df-4ddb-b69f-7c8cc4a7e776 | B7: Athanasios, hegoumenos of Vatopedi on Athos; Georgios III Hagiorites/Mt'ac'mindeli, hegoumenos of Iveron; Ioannes, hegoumenos of Zygos on Athos; Neophytos, hegoumenos of Lavra on Athos; Theophylaktos, protos of Mount Athos | C7: Neophytos 113 / Neophytos, hegoumenos of Lavra on Athos
A8: https://r11.eu/rdf/resource/9ff45a88-b859-468c-9115-7663e3b5d0b1 | B8: Athanasios, hegoumenos of Vatopedi on Athos; Georgios III Hagiorites/Mt'ac'mindeli, hegoumenos of Iveron; Ioannes, hegoumenos of Zygos on Athos; Neophytos, hegoumenos of Lavra on Athos; Theophylaktos, protos of Mount Athos | C8: Theophylaktos 117 / Theophylaktos, protos of Mount Athos
A9: https://r11.eu/rdf/resource/9ff45a88-b859-468c-9115-7663e3b5d0b1 | B9: Bartholomaios, monk and scribe at Esphigmenou on Athos; Theoktistos, hegoumenos of Esphigmenou and protos of Athos | C9: Theoktistos 107 / Theoktistos, hegoumenos of Esphigmenou and protos of Athos
A10: https://r11.eu/rdf/resource/3e963f4e-4672-4b9b-a488-88ca46aec3de | B10: Bartholomaios, monk and scribe at Esphigmenou on Athos; Theoktistos, hegoumenos of Esphigmenou and protos of Athos | C10: Bartholomaios 108 / Bartholomaios, monk and scribe at Esphigmenou on Athos
A11: https://r11.eu/rdf/resource/3e963f4e-4672-4b9b-a488-88ca46aec3de | B11: Bollig, I; de Lagarde, P | C11: 42584340 / Bollig, I
A12: https://r11.eu/rdf/resource/3e963f4e-4672-4b9b-a488-88ca46aec3de | B12: Bollig, I; de Lagarde, P | C12: 71399627 / de Lagarde, P
... A65: https://r11.eu/rdf/resource/b4d4c2b8-6a91-406e-9b2f-73d0d06bb33b | B65: Kale, wife of Symbatios Pakourianos; Eleutherios, notarios attached to the Hagioi Tessarakonta | C65: Eleutherios 101 / Eleutherios, notarios attached to the Hagioi Tessarakonta
B66: Kale, wife of Symbatios Pakourianos; Ioannes Phorites, notary at Constantinople | C66: Kale 102 / Kale, wife of Symbatios Pakourianos
B67: Kale, wife of Symbatios Pakourianos; Ioannes Phorites, notary at Constantinople | C67: Ioannes 190 / Ioannes Phorites, notary at Constantinople
A68: https://r11.eu/rdf/resource/b4d4c2b8-6a91-406e-9b2f-73d0d06bb33b | B68: Kurtz, Eduard; Drexl, Franz | C68: 59840374 / Kurtz, Eduard
A69: https://r11.eu/rdf/resource/b4d4c2b8-6a91-406e-9b2f-73d0d06bb33b | B69: Kurtz, Eduard; Drexl, Franz | C69: 35433472 / Drexl, Franz
A70: https://r11.eu/rdf/resource/72721472-d75a-4706-8735-541ed4a35362 | B70: Lefort, Jacques; Oikonomidès, Nicolas; Papachryssanthou, Denise; Kravari, Vassiliki; Métrévéli, Hélène | C70: 93206983 / Papachryssanthou, Denise
A71: https://r11.eu/rdf/resource/72721472-d75a-4706-8735-541ed4a35362 | B71: Lefort, Jacques; Oikonomidès, Nicolas; Papachryssanthou, Denise; Kravari, Vassiliki; Métrévéli, Hélène | C71: 71393851 / Lefort, Jacques
A72: https://r11.eu/rdf/resource/50f2406f-2cf5-4646-86dc-36aa01937a68 | B72: Lefort, Jacques; Oikonomidès, Nicolas; Papachryssanthou, Denise; Kravari, Vassiliki; Métrévéli, Hélène | C72: 14774616 / Oikonomidès, Nicolas
A73: https://r11.eu/rdf/resource/50f2406f-2cf5-4646-86dc-36aa01937a68 | B73: Lefort, Jacques; Oikonomidès, Nicolas; Papachryssanthou, Denise; Kravari, Vassiliki; Métrévéli, Hélène | C73: 31154757 / Kravari, Vassiliki
A74: https://r11.eu/rdf/resource/110d79e2-b7a2-4512-b242-1044d822495f | B74: Lefort, Jacques; Oikonomidès, Nicolas; Papachryssanthou, Denise; Kravari, Vassiliki; Métrévéli, Hélène | C74: 59302266 / Métrévéli, Hélène
A75: https://r11.eu/rdf/resource/110d79e2-b7a2-4512-b242-1044d822495f | B75: Lefort, Jacques; Oikonomidès, Nicolas; Papachryssanthou, Denise; Métrévéli, Hélène | C75: 93206983 / Papachryssanthou, Denise
A76: https://r11.eu/rdf/resource/44d70e9b-9b7d-47bc-86ab-10c04ccfb2af | B76: Lefort, Jacques; Oikonomidès, Nicolas; Papachryssanthou, Denise; Métrévéli, Hélène | C76: 71393851 / Lefort, Jacques
A77: https://r11.eu/rdf/resource/44d70e9b-9b7d-47bc-86ab-10c04ccfb2af | B77: Lefort, Jacques; Oikonomidès, Nicolas; Papachryssanthou, Denise; Métrévéli, Hélène | C77: 14774616 / Oikonomidès, Nicolas
A78: https://r11.eu/rdf/resource/797349c0-5e45-481b-bce9-92b2720a1b16 | B78: Lefort, Jacques; Oikonomidès, Nicolas; Papachryssanthou, Denise; Métrévéli, Hélène | C78: 59302266 / Métrévéli, Hélène
A79: https://r11.eu/rdf/resource/797349c0-5e45-481b-bce9-92b2720a1b16 | B79: Lemerle, Paul; Dagron, Gilbert; Ćirković, Sima M. | C79: 97996834 / Lemerle, Paul
... A149: https://r11.eu/rdf/resource/6527d8610385c | B149: Theodoulos, bishop of Ezoba; Leon Tzainos, protopapas of Ezoba bishopric; Ioannes, nomikos of Chrysopolis | C149: Leon 126 / Leon Tzainos, protopapas of Ezoba bishopric
B150: Theodoulos, bishop of Ezoba; Leon Tzainos, protopapas of Ezoba bishopric; Ioannes, nomikos of Chrysopolis | C150: Ioannes 183 / Ioannes, nomikos of Chrysopolis
B151: Theoktistos, hegoumenos of Esphigmenou and protos of Athos; Iakobos, monk and presbyter on Athos | C151: Theoktistos 107 / Theoktistos, hegoumenos of Esphigmenou and protos of Athos
B152: Theoktistos, hegoumenos of Esphigmenou and protos of Athos; Iakobos, monk and presbyter on Athos | C152: Iakobos 106 / Iakobos, monk and presbyter on Athos
B153: Vranoúsīs, Léandros I.; Nystazopoúlou-Pelekídou, María | C153: 51818933 / Vranoúsīs, Léandros I.
B154: Vranoúsīs, Léandros I.; Nystazopoúlou-Pelekídou, María | C154: 44710829 / Nystazopoúlou-Pelekídou, María
B155: Whitby, Mary; Jeffreys, Michael J.; Karágiṓrgou, ́Olga | C155: 34477027 / Whitby, Mary
B156: Whitby, Mary; Jeffreys, Michael J.; Karágiṓrgou, ́Olga | C156: 73866641 / Jeffreys, Michael J.
B157: Whitby, Mary; Jeffreys, Michael J.; Karágiṓrgou, ́Olga | C157: 253347413 / Karágiṓrgou, ́Olga
B158: Živojinović, Mirjana; Kravari, Vassiliki; Giros, Christophe | C158: 31154757 / Kravari, Vassiliki
B159: Živojinović, Mirjana; Kravari, Vassiliki; Giros, Christophe | C159: 24760554 / Giros, Christophe
B160: Živojinović, Mirjana; Kravari, Vassiliki; Giros, Christophe | C160: 14898912 / Živojinović, Mirjana
B161: ̓Orlándos, ̓Anastásios K.; Vranoúsīs, Léandros I. | C161: 100182818 / ̓Orlándos, ̓Anastásios K.
...

Sheet Actor groups
A1: Group identifier | B1: Group member | C1: Authority | D1: Authority group | E1: Based on | F1: Source text/publication | G1: Source text/reference | H1: Source text/excerpt
A2: Armenian attackers of Berkri | B2: T3 Gandzi / Ganji, Armenian išxan | C2: T2 Mattheos / Matthew of Edessa | F2: Chronicle of Matthew | G2: I.65 | H2: Գանձի և ամենայն զօրքն իւր անցին ի քաղաքին Բերկրի

Sheet Places
A1: PBW key | B1: Reference name | C1: Pleiades ID | D1: Geonames ID | E1: Wikidata ID | F1: Location coordinates | G1: Place type | H1: Earliest existence | I1: Latest existence | J1: Succeeds place | K1: Incorporates place | L1: Had population group | M1: Authority | N1: Authority group | O1: Based on | P1: Source text/publication | Q1: Source text/reference | R1: Source text/excerpt
A2: 10518 | B2: 'Arqa (Syria) | C2: https://pleiades.stoa.org/places/668198 | M2: 44335536 / Roueché, Charlotte
A3: 8938 | B3: Abchasia | D3: https://www.geonames.org/6643410 | M3: 44335536 / Roueché, Charlotte
A4: 9674 | B4: Abroba (Bulgaria) | D4: https://www.geonames.org/725520 | M4: 44335536 / Roueché, Charlotte
A5: 8966 | B5: Abydos | C5: https://pleiades.stoa.org/places/501325 | M5: 44335536 / Roueché, Charlotte
A6: 10946 | B6: Acerenza | C6: https://pleiades.stoa.org/places/442436 | M6: 44335536 / Roueché, Charlotte
A7: 10244 | B7: Acheloos | D7: https://www.geonames.org/736832 | M7: 44335536 / Roueché, Charlotte
A8: 9850 | B8: Achyraous | D8: https://www.geonames.org/322165 | M8: 44335536 / Roueché, Charlotte
A9: 10383 | B9: Acre | C9: https://pleiades.stoa.org/places/678010 | M9: 44335536 / Roueché, Charlotte
A10: 11282 | B10: Acre: Church of the Holy Cross | C10: https://pleiades.stoa.org/places/678010 | M10: 44335536 / Roueché, Charlotte
A11: 11065 | B11: Adada | C11: https://pleiades.stoa.org/places/638733 | M11: 44335536 / Roueché, Charlotte
A12: 9262 | B12: Adana | C12: https://pleiades.stoa.org/places/648548 | M12: 44335536 / Roueché, Charlotte
A13: 9978 | B13: Adramyttion | C13: https://pleiades.stoa.org/places/550403 | M13: 44335536 / Roueché, Charlotte
A14: 10000 | B14: Adraneia | C14: https://pleiades.stoa.org/places/609395 | M14: 44335536 / Roueché, Charlotte
A15: 10356 | B15: Adrianople (Lykaonia) | C15: https://pleiades.stoa.org/places/638852 | M15: 44335536 / Roueché, Charlotte
A16: 9452 | B16: Adrianople (Thrace) | C16: https://pleiades.stoa.org/places/5014275 | M16: 44335536 / Roueché, Charlotte
A17: 11416 | B17: Adrianople (Thrace): bridge over three rivers | C17: https://pleiades.stoa.org/places/5014275 | M17: 44335536 / Roueché, Charlotte
A18: 11344 | B18: Adrianople (Thrace): House of Silvestros | C18: https://pleiades.stoa.org/places/5014275 | M18: 44335536 / Roueché, Charlotte
A19: 9541 | B19: Adrianople (Thrace): Theometor | C19: https://pleiades.stoa.org/places/5014275 | M19: 44335536 / Roueché, Charlotte
A20: 9870 | B20: Aegean Sea | C20: https://pleiades.stoa.org/places/560221 | D20: https://www.geonames.org/265695 | M20: 44335536 / Roueché, Charlotte
A21: 11422 | B21: Aeironesion (Sazan island) | C21: https://pleiades.stoa.org/places/481981 | M21: 44335536 / Roueché, Charlotte
A22: 9558 | B22: Aetos (Macedonia) | D22: https://www.geonames.org/736989 | M22: 44335536 / Roueché, Charlotte
A23: 10030 | B23: Agrai | C23: https://pleiades.stoa.org/places/638735 | M23: 44335536 / Roueché, Charlotte
A24: 11421 | B24: Aigina | C24: https://pleiades.stoa.org/places/579844 | M24: 44335536 / Roueché, Charlotte
A25: 9160 | B25: Ainos | C25: https://pleiades.stoa.org/places/501337 | M25: 44335536 / Roueché, Charlotte
A26: 9979 | B26: Akmoneia | C26: https://pleiades.stoa.org/places/609293 | M26: 44335536 / Roueché, Charlotte
A27: 10445 | B27: Akrasos | C27: https://pleiades.stoa.org/places/554181 | M27: 44335536 / Roueché, Charlotte
A28: 11420 | B28: Akrokorinthos | C28: https://pleiades.stoa.org/places/570059 | M28: 44335536 / Roueché, Charlotte
A29: 11535 | B29: Akrokos (Phrygia) | C29: https://pleiades.stoa.org/places/609296 | M29: 44335536 / Roueché, Charlotte
A30: 11554 | B30: Akronios (Phrygia) | C30: https://pleiades.stoa.org/places/612330 | M30: 44335536 / Roueché, Charlotte
A31: 10549 | B31: al-Arish | C31: https://pleiades.stoa.org/places/688016 | M31: 44335536 / Roueché, Charlotte
A32: 11750 | B32: al-Haditha (Iraq) | D32: https://www.geonames.org/96309 | M32: 44335536 / Roueché, Charlotte
A33: 11744 | B33: al-Hilla | C33: https://pleiades.stoa.org/places/434655355 | M33: 44335536 / Roueché, Charlotte
A34: 9966 | B34: Alabanda | C34: https://pleiades.stoa.org/places/599479 | M34: 44335536 / Roueché, Charlotte
A35: 10686 | B35: Albania (Caucasus) | C35: https://pleiades.stoa.org/places/863731 | M35: 44335536 / Roueché, Charlotte
A36: 11563 | B36: Albano (not far from Rome) | D36: https://www.geonames.org/3183356 | M36: 44335536 / Roueché, Charlotte
A37: 10512 | B37: Albara (Syria) | D37: https://www.geonames.org/173999 | M37: 44335536 / Roueché, Charlotte
A38: 11284 | B38: Aleppo | C38: https://pleiades.stoa.org/places/658409 | M38: 44335536 / Roueché, Charlotte
A39: 11576 | B39: Aleppo: Great Mosque | C39: https://pleiades.stoa.org/places/658409 | D39: https://www.geonames.org/7745901 | M39: 44335536 / Roueché, Charlotte
A40: 11286 | B40: Aleppo: Palace | C40: https://pleiades.stoa.org/places/658409 | M40: 44335536 / Roueché, Charlotte
...

Sheet Text publications
A1: Text identifier | B1: Text name | C1: Creation date | D1: Author | E1: Author group | F1: Edition | G1: Editor | H1: Editor group | I1: Authority | J1: Authority group | K1: Source text/publication | L1: Source text/reference | M1: Source text/excerpt
A2: Albert of Aachen | B2: Historia Hierosolymitana | D2: Albert 26101 / Albert of Aachen | F2: Historia Ierosolimitana, History of the Journey to Jerusalem, Oxford 2007 | G2: 93497875 / Edgington, Susan B. | I2: Albert 26101 / Albert of Aachen | K2: Albert of Aachen | L2: I.1
A3: Alexios Stoudites | B3: The Decrees of Alexios Stoudites | D3: Alexios 11 / Alexios Stoudites, patriarch of Constantinople | F3: Erlasse des Patriarchen von Konstantinopel Alexios Studites, Kiel: Festschrift der Universität Kiel, 1911 | G3: 37668465 / Ficker, Gerhard | I3: 37668465 / Ficker, Gerhard | K3: Alexios Stoudites | L3: title, p. 4
A4: Anna Komnene | B4: Alexias | D4: Anna 62 / Anna Komnene, daughter of Alexios I and historian | F4: Annae Comnenae Alexias, Corpus fontium historiae Byzantinae 40/1, Berlin – New York 2001 | H4: Reinsch, Diether Roderich; Kambylis, Athanasios | I4: Anna 62 / Anna Komnene, daughter of Alexios I and historian | K4: Anna Komnene | L4: 6.17-21
A5: Annales Barenses | B5: Annales Barenses | F5: Annales Barenses, Monumenta Germaniae historica, Scriptores V, Hanover 1844, 52-56 | G5: 54236315 / Pertz, Georg Heinrich | I5: 54236315 / Pertz, Georg Heinrich | K5: Annales Barenses
A6: Anonymus Barensis | B6: Anonymus Barensis | D6: 13129565 / Anonymus Barensis | F6: Anonymi Barensis Chronicon, Rerum Italicarum scriptores V, Milan 1724, 147-156 | G6: 68933348 / Muratori, Lodovico Antonio | I6: 68933348 / Muratori, Lodovico Antonio | K6: Anonymus Barensis
A7: Aristakes | B7: Patmutʿiwn | D7: Aristakes 101 / Aristakes Lastivertc'i / of Lastivert, Armenian historian | F7: Récit des malheurs de la nation arménienne, Brussels 1973 | H7: Canard, Marius; Pērpērean, Hayk | I7: Aristakes 101 / Aristakes Lastivertc'i / of Lastivert, Armenian historian | K7: Aristakes | L7: 142.1-145.30 (129-132)
A8: Attaleiates: Diataxis | B8: Diataxis | D8: Michael 202 / Michael Attaleiates | F8: “La diataxis de Michel Attaliate”, Revue des études byzantines 39 (1981) 5-143 | G8: 231073465 / Gautier, Paul | I8: Michael 202 / Michael Attaleiates | K8: Attaleiates: Diataxis | L8: 17.1, 83.1087-90
A9: Attaleiates: History | B9: Attaliatae Historia | D9: Michael 202 / Michael Attaleiates | F9: Michaelis Attaliatae Historia, Corpus scriptorum historiae Byzantinae 3, Bonn 1853 | H9: Brunet de Presle, Wladimir; Bekker, Immanuel | I9: Michael 202 / Michael Attaleiates | K9: Attaleiates: History | L9: 322.10-19 / 229.17-24
A10: Basilakios, Orationes et epistulae | B10: Basilacae Orationes et epistolae | D10: Nikephoros 17003 / Nikephoros Basilakios, writer involved in doctrinal disputes | F10: Nicephori Basilacae Orationes et epistolae, Leipzig 1984 | G10: 27081575 / Garzya, Antonio | I10: Nikephoros 17003 / Nikephoros Basilakios, writer involved in doctrinal disputes | K10: Basilakios, Orationes et epistulae | L10: 1.1-9.22
A11: Boilas | B11: Testament of Boilas | D11: Eustathios 105 / Eustathios Boilas | F11: “Le testament d’Eustathios Boïlas (Avril 1059)”, Cinq études sur le XIe siècle byzantin, Paris (1977) 15-63 | G11: 97996834 / Lemerle, Paul | I11: Eustathios 105 / Eustathios Boilas | K11: Boilas | L11: 29.283-284
A12: Bryennios | B12: Hyle historias | D12: Nikephoros 117 / Nikephoros Bryennios, kaisar, husband of Anna Komnene | F12: Nicéphore Bryennios: Histoire. Introduction, texte, traduction et notes, Brussels 1975 | G12: 231073465 / Gautier, Paul | I12: Nikephoros 117 / Nikephoros Bryennios, kaisar, husband of Anna Komnene | K12: Bryennios | L12: 71.26-73.11
A13: Christophoros of Mitylene | B13: Poems | D13: Christophoros 13102 / Christophoros of Mitylene, poet | F13: Die Gedichte des Christophoros Mitylenaios, Leipzig 1903 | G13: 59840374 / Kurtz, Eduard | I13: 59840374 / Kurtz, Eduard | K13: Christophoros of Mitylene | L13: title, p. 1
A14: Christos Philanthropos, note | F14: “Commémoraisons des Comnènes dans le typikon liturgique du monastère du Christ Philanthrope (ms. Panaghia Kamariotissa 29)”, Revue des études Byzantines 63 (2005), 41-69 | H14: Rízou-Kouroúpou, Matoúla; Vannier, Jean-François | J14: Rízou-Kouroúpou, Matoúla; Vannier, Jean-François | K14: Christos Philanthropos, note
A15: Chronicle of Matthew | B15: Zhamanakagrut‘iwn | D15: T2 Mattheos / Matthew of Edessa | F15: Žamanakagrutʿiwn, Vałaršapat, 1898 | H15: Melikʻ-Adamyan, Mambre; Ter-Mikʻayelyan, Nerses | I15: T2 Mattheos / Matthew of Edessa | K15: Chronicle of Matthew | L15: II.i | M15: Եւ վասն այսորիկ ես Մատթէոս Ուռհայեցի և վանական` զաշխատութեան զգործս իմ ոչինչ համարեցայ
A16: Chronicle of Matthew (Dostourian) | B16: Armenia and the Crusades | D16: T2 Mattheos / Matthew of Edessa | F16: Armenia and the Crusades: The Chronicle of Matthew of Edessa. Translated by Ara Edmond Dostourian. Second edition. Belmont, MA: Armenian Heritage Press, 2014. | G16: 77829335 / Dostourian, Ara Edmond | I16: 77829335 / Dostourian, Ara Edmond | K16: Chronicle of Matthew (Dostourian) | L16: Introduction
A17: Chrysobull of 1079 | F17: “Un chrysobulle de Nicéphore Botaneiatès à souscription synodale”, Byzantion 29 (1959) 29-41 | G17: 88739139 / Gouillard, Jean | I17: 88739139 / Gouillard, Jean | K17: Chrysobull of 1079
A18: Clement III to Basileios of Calabria | B18: Clement III to Basileios of Calabria | D18: Klemes 23 / antipope Clement III (Guibert of Ravenna) | F18: “Die Unionsverhandlungen zwischen Kaiser Alexios I. und Papst Urban II. im Jahre 1089″, Byzantinische Zeitschrift 28 (1928), 59-60 | G18: 7485449 / Holtzmann, Walther | I18: 51999624 / Ryder, Judith R. | K18: Clement III to Basileios of Calabria | L18: 59.1-60.5
A19: Dionysiou | B19: Deed of guarantee of Konstantinos Phasoulos | D19: Ioannes 411 / Ioannes, klerikos of Hagia Sophia (of Thessalonike) and nomikos | F19: Actes de Dionysiou, Archives de l’Athos IV, Paris 1968, pp. 35-42 | G19: 14774616 / Oikonomidēs, Nicolas | I19: 316793603 / Papacostas, Tassos | K19: Dionysiou | L19: 41.40-42.50
A20: Docheiariou 1 | B20: Hypomnema of Konstantinos Kamateros | D20: Konstantinos 256 / Konstantinos Kamateros, krites of Boleron, Strymon and Thessalonike | F20: Actes de Docheiariou, Archives de l’Athos XIII, Paris 1984, 53 | G20: 14774616 / Oikonomidēs, Nicolas | I20: 316793603 / Papacostas, Tassos | K20: Docheiariou 1 | L20: 53.2-35
A21: Docheiariou 2a | B21: Pittakion of Alexios I | E21: Niketas Xiphilinos, krites and anagrapheus of Boleron, Strymon and Thessalonike; Emperor Alexios I Komnenos | F21: Actes de Docheiariou, Archives de l’Athos XIII, Paris 1984, 58 | G21: 14774616 / Oikonomidēs, Nicolas | I21: 316793603 / Papacostas, Tassos | K21: Docheiariou 2a | L21: 58.1-59.40
A22: Docheiariou 2b | B22: Prostaxis of Anna Dalassene | E22: Niketas Xiphilinos, krites and anagrapheus of Boleron, Strymon and Thessalonike; Anna Dalassene | F22: Actes de Docheiariou, Archives de l’Athos XIII, Paris 1984, 58-59 | G22: 14774616 / Oikonomidēs, Nicolas | I22: 316793603 / Papacostas, Tassos | K22: Docheiariou 2b | L22: 58.1-59.40
A23: Documents 4 | B23: On Ordinations | D23: Niketas 135 / Niketas, metropolitan of Ankyra [1072, 1079, 1082] | F23: Documents inédits d'ecclésiologie byzantine, Leuven 1966, pp. 176-206 | G23: 19676388 / Darrouzès, Jean | I23: Niketas 135 / Niketas, metropolitan of Ankyra [1072, 1079, 1082] | K23: Documents 4 | L23: 176-206
A24: Domenico of Grado | B24: Domenico of Grado to Petros of Antioch | D24: Dominikos 101 / Domenico, archbishop of Grado or Aquileia, patriarch of Venice | F24: Acta et scripta quae de controversiis ecclesiae graecae et latinae saeculo undecimo composita extant, Leipzig and Marburg 1861, pp. 205-208 | G24: 29618378 / Will, Cornelius | I24: Dominikos 101 / Domenico, archbishop of Grado or Aquileia, patriarch of Venice | K24: Domenico of Grado | L24: 205.3-208.16
A25: Eleousa: Acts | B25: Chrysobull to Eleousa monastery | D25: Alexios 1 / Emperor Alexios I Komnenos | F25: “Le monastère de Notre-Dame de Pitié en Macédoine”, Izvestija Russkogo Arheologičeskogo Instituta v Konstantinopole 6 (1900) 25-27 | G25: 51721803 / Petit, Louis | I25: 316793603 / Papacostas, Tassos | K25: Eleousa: Acts | L25: 26.19-27.8
A26: Eleousa: Typikon | B26: Typikon of Eleousa monastery | D26: Manuel 63 / Manuel, bishop of Stroumitza (Tiberioupolis) | F26: “Le monastère de Notre-Dame de Pitié en Macédoine”, Izvestija Russkogo Arheologičeskogo Instituta v Konstantinopole 6 (1900) 69-125 | G26: 51721803 / Petit, Louis | I26: 34477027 / Whitby, Mary | K26: Eleousa: Typikon | L26: 93.24-8
A27: Esphigmenou 1 | B27: Deed of sale 1034 | E27: Dionysios, monk and scribe at Berroiotou on Athos; Germanos, hegoumenos of Theotokos Katadaimonon on Athos; Petros, hegoumenos of Theotokos Katadaimonon on Athos | F27: Actes d’Esphigménou, Archives de l’Athos VI, Paris 1973, 41-42 | G27: 71393851 / Lefort, Jacques | I27: 316793603 / Papacostas, Tassos | K27: Esphigmenou 1 | L27: 42.31-32
A28: Esphigmenou 2 | B28: Deed of Theoktistos to Nikephoros | E28: Bartholomaios, monk and scribe at Esphigmenou on Athos; Theoktistos, hegoumenos of Esphigmenou and protos of Athos | F28: Actes d’Esphigménou, Archives de l’Athos VI, Paris 1973, 45-46 | G28: 71393851 / Lefort, Jacques | I28: 316793603 / Papacostas, Tassos | K28: Esphigmenou 2 | L28: 46.37-39
A29: Esphigmenou 3 | B29: Guarantee of Theodoros of Galaiagra | E29: Theodoros, monk at Galeagra on Athos; Iakobos, monk at Galeagra on Athos | F29: Actes d’Esphigménou, Archives de l’Athos VI, Paris 1973, 48-49 | G29: 71393851 / Lefort, Jacques | I29: 316793603 / Papacostas, Tassos | K29: Esphigmenou 3 | L29: 48.1-49.34
A30: Esphigmenou 4 | B30: Deed of Nikolaos protospatharios | D30: Nikolaos 226 / Nikolaos, protospatharios and man of krites of the velon Christophoros | F30: Actes d’Esphigménou, Archives de l’Athos VI, Paris 1973, 52-54 | G30: 71393851 / Lefort, Jacques | I30: 316793603 / Papacostas, Tassos | K30: Esphigmenou 4 | L30: 53.20-26
A31: Esphigmenou 4a | B31: Parekbolaion of Christophoros krites | E31: Christophoros, krites of the velon and of Boleron, Strymon and Thessalonike; Nikolaos, protospatharios and man of krites of the velon Christophoros | F31: Actes d’Esphigménou, Archives de l’Athos VI, Paris 1973, 52-53 | G31: 71393851 / Lefort, Jacques | I31: 316793603 / Papacostas, Tassos | K31: Esphigmenou 4a | L31: 52.2-53.11
A32: Esphigmenou 5 | B32: Deed of Euthymios | D32: Euthymios 113 / Euthymios, anagrapheus of Boleron, Strymon and Thessalonike | F32: Actes d’Esphigménou, Archives de l’Athos VI, Paris 1973, 57-58 | G32: 71393851 / Lefort, Jacques | I32: 316793603 / Papacostas, Tassos | K32: Esphigmenou 5 | L32: 57.1-58.34
A33: Eustathios Romaios Peira | B33: Peira | D33: Eustathios 61 / Eustathios Romaios | F33: “Πεῖρα Εὐσταθίου τοῦ Ῥωμαίου”, Jus Graecoromanum vol.4, Athens 1931 | G33: 111939078 / Zepos, Panagiōtēs | I33: Eustathios 61 / Eustathios Romaios | K33: Eustathios Romaios Peira | L33: Peira, tit.
A34: Eustathios Romaios RPA | B34: Peri disexadelphōn | D34: Eustathios 61 / Eustathios Romaios | F34: Σύνταγμα τῶν θείων καὶ ἱερῶν κανόνων, vol. 5, Athens 1855, 32-36 | H34: Rállēs, Geṓrgios A.; Potlēs, Michaēl | I34: Eustathios 61 / Eustathios Romaios | K34: Eustathios Romaios RPA | L34: Ralles-Potles V, 32-36
A35: Eustathios Romaios RPB | B35: Hypomnēma peri duō exadelphōn labontōn duo exadelphas | D35: Eustathios 61 / Eustathios Romaios | F35: Σύνταγμα τῶν θείων καὶ ἱερῶν κανόνων, vol. 5, Athens 1855, 341-353 | H35: Rállēs, Geṓrgios A.; Potlēs, Michaēl | I35: Eustathios 61 / Eustathios Romaios | K35: Eustathios Romaios RPB | L35: Ralles-Potles V, 341
A36: Eustathios Romaios Schminck I | B36: Marriage of Ioannes and Maria | D36: Eustathios 61 / Eustathios Romaios | F36: “Vier eherechtliche Entscheidungen aus dem 11. Jahrhundert”, Fontes Minores 3 (1979) 221-279 | G36: 62165959 / Schminck, Andreas | I36: Eustathios 61 / Eustathios Romaios | K36: Eustathios Romaios Schminck I | L36: Schminck I, 1-111
A37: Eustathios Romaios Schminck II | B37: Marriage of Theophylact and Theophano | D37: Eustathios 61 / Eustathios Romaios | F37: “Vier eherechtliche Entscheidungen aus dem 11. Jahrhundert”, Fontes Minores 3 (1979) 221-279 | G37: 62165959 / Schminck, Andreas | I37: 62165959 / Schminck, Andreas | K37: Eustathios Romaios Schminck II | L37: p. 250
A38: Eustathios Romaios Schminck III | B38: Marriage of the daughter of Brachamios | D38: Eustathios 61 / Eustathios Romaios | F38: “Vier eherechtliche Entscheidungen aus dem 11. Jahrhundert”, Fontes Minores 3 (1979) 221-279 | G38: 62165959 / Schminck, Andreas | I38: Eustathios 61 / Eustathios Romaios | K38: Eustathios Romaios Schminck III | L38: Schminck III, 1-153
A39: Eustathios: Capture of Thessalonike | B39: De Thessalonica a Latinis capta | D39: Eustathios 20147 / Eustathios, metropolitan of Thessalonike | F39: La espugnazione di Tessalonica, Palermo 1961 | G39: 69687416 / Kyriakides, Stilpon Paraskeua | I39: Eustathios 20147 / Eustathios, metropolitan of Thessalonike | K39: Eustathios: Capture of Thessalonike | L39: 2.10-4.21
A40: Fulcher of Chartres | B40: Fulcheri Carnotensis Historia Hierosolymitana | D40: Fulcher 101 / Fulcher of Chartres, historian | F40: Fulcheri Carnotensis Historia Hierosolymitana (1095-1127), Heidelberg 1913 | G40: 5023204 / Hagenmeyer, Heinrich | I40: Fulcher 101 / Fulcher of Chartres, historian | K40: Fulcher of Chartres | L40: 41030
...

Sheet Correspondence
A1: Letter sent | B1: Text therein | C1: From whom | D1: From group | E1: To whom | F1: To group | G1: When sent | H1: When received | I1: Where sent | J1: Where received | K1: Authority | L1: Authority group | M1: Based on | N1: Source text/publication | O1: Source text/reference | P1: Source text/excerpt
A2: Psellos, Letter 1 | B2: Psellos Papaioannou 1 | C2: Michael 61 / Michael Psellos (named Konstantinos till tonsure in 1054) | E2: Aikaterine 101 / Aikaterine of Bulgaria, wife of Isaakios I Komnenos | G2: J 1059 | K2: 60972463 / Papaioannou, Stratis | N2: Psellos Papaioannou 1 | O2: p. 1
A3: Psellos, Letter 2 | B3: Psellos Papaioannou 2 | C3: Michael 61 / Michael Psellos (named Konstantinos till tonsure in 1054) | E3: Aimilianos 61 / Aimilianos, patriarch of Antioch | I3: Antioch (on the Orontes) | K3: 60972463 / Papaioannou, Stratis | N3: Psellos Papaioannou 2 | O3: p. 3
A4: Psellos, Letter 3 | B4: Psellos Papaioannou 3 | C4: Michael 61 / Michael Psellos (named Konstantinos till tonsure in 1054) | E4: Aimilianos 61 / Aimilianos, patriarch of Antioch | I4: Antioch (on the Orontes) | K4: 60972463 / Papaioannou, Stratis | N4: Psellos Papaioannou 3 | O4: p. 4
A5: Psellos, Letter 4 | B5: Psellos Papaioannou 4 | C5: Michael 61 / Michael Psellos (named Konstantinos till tonsure in 1054) | E5: Aimilianos 61 / Aimilianos, patriarch of Antioch | I5: Antioch (on the Orontes) | K5: 60972463 / Papaioannou, Stratis | N5: Psellos Papaioannou 4 | O5: p. 6
A6: Psellos, Letter 5 | B6: Psellos Papaioannou 5 | C6: Michael 61 / Michael Psellos (named Konstantinos till tonsure in 1054) | E6: Aimilianos 61 / Aimilianos, patriarch of Antioch | I6: Antioch (on the Orontes) | K6: 60972463 / Papaioannou, Stratis | N6: Psellos Papaioannou 5 | O6: p. 7
A7: Psellos, Letter 6 | B7: Psellos Papaioannou 6 | C7: Michael 61 / Michael Psellos (named Konstantinos till tonsure in 1054) | E7: Aimilianos 61 / Aimilianos, patriarch of Antioch | I7: Antioch (on the Orontes) | K7: 60972463 / Papaioannou, Stratis | N7: Psellos Papaioannou 6 | O7: p. 10
A8: Psellos, Letter 7 | B8: Psellos Papaioannou 7 | C8: Michael 61 / Michael Psellos (named Konstantinos till tonsure in 1054) | E8: Aimilianos 61 / Aimilianos, patriarch of Antioch | I8: Antioch (on the Orontes) | K8: 60972463 / Papaioannou, Stratis | N8: Psellos Papaioannou 7 | O8: p. 12
A9: Psellos, Letter 8 | B9: Psellos Papaioannou 8 | C9: Michael 61 / Michael Psellos (named Konstantinos till tonsure in 1054) | E9: Aimilianos 61 / Aimilianos, patriarch of Antioch | I9: Antioch (on the Orontes) | K9: 60972463 / Papaioannou, Stratis | N9: Psellos Papaioannou 8 | O9: p. 14
A10: Psellos, Letter 9 | B10: Psellos Papaioannou 9 | C10: Michael 61 / Michael Psellos (named Konstantinos till tonsure in 1054) | E10: Aimilianos 61 / Aimilianos, patriarch of Antioch | I10: Antioch (on the Orontes) | K10: 60972463 / Papaioannou, Stratis | N10: Psellos Papaioannou 9 | O10: p. 15
A11: Psellos, Letter 10 | B11: Psellos Papaioannou 10 | C11: Michael 61 / Michael Psellos (named Konstantinos till tonsure in 1054) | E11: Aimilianos 61 / Aimilianos, patriarch of Antioch | I11: Antioch (on the Orontes) | K11: 60972463 / Papaioannou, Stratis | N11: Psellos Papaioannou 10 | O11: p. 19
A12: Psellos, Letter 11 | B12: Psellos Papaioannou 11 | C12: Michael 61 / Michael Psellos (named Konstantinos till tonsure in 1054) | E12: Aimilianos 61 / Aimilianos, patriarch of Antioch | I12: Antioch (on the Orontes) | K12: 60972463 / Papaioannou, Stratis | N12: Psellos Papaioannou 11 | O12: p. 22
A13: Psellos, Letter 12 | B13: Psellos Papaioannou 12 | C13: Michael 61 / Michael Psellos (named Konstantinos till tonsure in 1054) | E13: Aimilianos 61 / Aimilianos, patriarch of Antioch | I13: Antioch (on the Orontes) | K13: 60972463 / Papaioannou, Stratis | N13: Psellos Papaioannou 12 | O13: p. 25
A14: Psellos, Letter 13 | B14: Psellos Papaioannou 13 | C14: Michael 61 / Michael Psellos (named Konstantinos till tonsure in 1054) | E14: Aimilianos 61 / Aimilianos, patriarch of Antioch | I14: Antioch (on the Orontes) | K14: 60972463 / Papaioannou, Stratis | N14: Psellos Papaioannou 13 | O14: p. 26
... A17: Psellos, Letter 16 | B17: Psellos Papaioannou 16 | C17: Michael 61 / Michael Psellos (named Konstantinos till tonsure in 1054) | E17: Aimilianos 61 / Aimilianos, patriarch of Antioch | I17: Antioch (on the Orontes) | K17: 60972463 / Papaioannou, Stratis | N17: Psellos Papaioannou 16 | O17: p. 41
A18: Psellos, Letter 17 | B18: Psellos Papaioannou 17 | C18: Michael 61 / Michael Psellos (named Konstantinos till tonsure in 1054) | E18: Theodoros 106 / Theodoros (Leon) Alopos, envoy of Michael VI to Isaakios Komnenos | G18: J 1059 | K18: 60972463 / Papaioannou, Stratis | N18: Psellos Papaioannou 17 | O18: p. 44
A19: Psellos, Letter 18 | B19: Psellos Papaioannou 18 | C19: Michael 61 / Michael Psellos (named Konstantinos till tonsure in 1054) | E19: Anonymus 2545 / Aristenos, correspondent of Michael Psellos | K19: 60972463 / Papaioannou, Stratis | N19: Psellos Papaioannou 18 | O19: p. 46
A20: Psellos, Letter 19 | B20: Psellos Papaioannou 19 | C20: Michael 61 / Michael Psellos (named Konstantinos till tonsure in 1054) | E20: Anonymus 2300 / Aristenos, protoasekretis | K20: 60972463 / Papaioannou, Stratis | N20: Psellos Papaioannou 19 | O20: p. 48
A21: Psellos, Letter 20 | B21: Psellos Papaioannou 20 | C21: Michael 61 / Michael Psellos (named Konstantinos till tonsure in 1054) | E21: Anonymus 2300 / Aristenos, protoasekretis | K21: 60972463 / Papaioannou, Stratis | N21: Psellos Papaioannou 20 | O21: p. 49
A22: Psellos, Letter 21 | B22: Psellos Papaioannou 21 | C22: Michael 61 / Michael Psellos (named Konstantinos till tonsure in 1054) | E22: Anonymus 2300 / Aristenos, protoasekretis | G22: J 1068 [TAQ] | K22: 60972463 / Papaioannou, Stratis | N22: Psellos Papaioannou 21 | O22: p. 51
A23: Psellos, Letter 22 | B23: Psellos Papaioannou 22 | C23: Michael 61 / Michael Psellos (named Konstantinos till tonsure in 1054) | E23: Anonymus 2300 / Aristenos, protoasekretis | G23: J 1068 [TAQ] | K23: 60972463 / Papaioannou, Stratis | N23: Psellos Papaioannou 22 | O23: p. 51
A24: Psellos, Letter 23 | B24: Psellos Papaioannou 23 | C24: Michael 61 / Michael Psellos (named Konstantinos till tonsure in 1054) | E24: Anonymus 2300 / Aristenos, protoasekretis | G24: J 1068 [TAQ] | K24: 60972463 / Papaioannou, Stratis | N24: Psellos Papaioannou 23 | O24: p. 54
A25: Psellos, Letter 23 | B25: Psellos Papaioannou 23 | C25: Michael 61 / Michael Psellos (named Konstantinos till tonsure in 1054) | E25: Leon 101 / Leon, epi ton deeseon, killed at Mantzikert | G25: J 1068 [TAQ] | K25: 60972463 / Papaioannou, Stratis | N25: Psellos Papaioannou 23 | O25: p. 54
A26: Psellos, Letter 23 | B26: Psellos Papaioannou 23 | C26: Michael 61 / Michael Psellos (named Konstantinos till tonsure in 1054) | E26: Ioannes 20154 / Ioannes Libellisios | G26: J 1068 [TAQ] | K26: 60972463 / Papaioannou, Stratis | N26: Psellos Papaioannou 23 | O26: p. 54
A27: Psellos, Letter 24 | B27: Psellos Papaioannou 24 | C27: Michael 61 / Michael Psellos (named Konstantinos till tonsure in 1054) | E27: Basileios 2103 / Basileios, epi tou kanikleiou | G27: J 1068 [TAQ] | K27: 60972463 / Papaioannou, Stratis | N27: Psellos Papaioannou 24 | O27: p. 60
A28: Psellos, Letter 25 | B28: Psellos Papaioannou 25 | C28: Michael 61 / Michael Psellos (named Konstantinos till tonsure in 1054) | E28: Basileios 2103 / Basileios, epi tou kanikleiou | G28: J 1068 [TAQ] | K28: 60972463 / Papaioannou, Stratis | N28: Psellos Papaioannou 25 | O28: p. 62
A29: Psellos, Letter 26 | B29: Psellos Papaioannou 26 | C29: Michael 61 / Michael Psellos (named Konstantinos till tonsure in 1054) | E29: Basileios 2103 / Basileios, epi tou kanikleiou | G29: J 1072 | K29: 60972463 / Papaioannou, Stratis | N29: Psellos Papaioannou 26 | O29: p. 64
A30: Psellos, Letter 27 | B30: Psellos Papaioannou 27 | C30: Michael 61 / Michael Psellos (named Konstantinos till tonsure in 1054) | E30: Basileios 2105 / Basileios, krites of Armeniakon | I30: Armeniakon | K30: 60972463 / Papaioannou, Stratis | N30: Psellos Papaioannou 27 | O30: p. 65
A31: Psellos, Letter 28 | B31: Psellos Papaioannou 28 | C31: Michael 61 / Michael Psellos (named Konstantinos till tonsure in 1054) | E31: Basileios 2104 / Basileios, krites (?) of Cappadocia | I31: Cappadocia | K31: 60972463 / Papaioannou, Stratis | N31: Psellos Papaioannou 28 | O31: p. 67
A32: Psellos, Letter 29 | B32: Psellos Papaioannou 29 | C32: Michael 61 / Michael Psellos (named Konstantinos till tonsure in 1054) | E32: Basileios 180 / Basileios, metropolitan of Nikomedeia [1072] | G32: J 1064 - J 1075 | I32: Nikomedeia | K32: 60972463 / Papaioannou, Stratis | N32: Psellos Papaioannou 29 | O32: p. 70
A33: Psellos, Letter 30 | B33: Psellos Papaioannou 30 | C33: Michael 61 / Michael Psellos (named Konstantinos till tonsure in 1054) | E33: Basileios 180 / Basileios, metropolitan of Nikomedeia [1072] | I33: Nikomedeia | K33: 60972463 / Papaioannou, Stratis | N33: Psellos Papaioannou 30 | O33: p. 71
A34: Psellos, Letter 31 | B34: Psellos Papaioannou 31 | C34: Michael 61 / Michael Psellos (named Konstantinos till tonsure in 1054) | E34: Anonymus 2223 / Bourtzes (Ioannes?), correspondent of Michael Psellos | K34: 60972463 / Papaioannou, Stratis | N34: Psellos Papaioannou 31 | O34: p. 72
A35: Psellos, Letter 32 | B35: Psellos Papaioannou 32 | C35: Michael 61 / Michael Psellos (named Konstantinos till tonsure in 1054) | E35: Georgios 2102 / Georgios, aktouarios | K35: 60972463 / Papaioannou, Stratis | N35: Psellos Papaioannou 32 | O35: p. 76
A36: Psellos, Letter 33 | B36: Psellos Papaioannou 33 | C36: Michael 61 / Michael Psellos (named Konstantinos till tonsure in 1054) | E36: Georgios 2101 / Georgios, correspondent of Michael Psellos | K36: 60972463 / Papaioannou, Stratis | N36: Psellos Papaioannou 33 | O36: p. 78
A37: Psellos, Letter 34 | B37: Psellos Papaioannou 34 | C37: Michael 61 / Michael Psellos (named Konstantinos till tonsure in 1054) | E37: Georgios 2101 / Georgios, correspondent of Michael Psellos | K37: 60972463 / Papaioannou, Stratis | N37: Psellos Papaioannou 34 | O37: p. 79
A38: Psellos, Letter 35 | B38: Psellos Papaioannou 35 | C38: Michael 61 / Michael Psellos (named Konstantinos till tonsure in 1054) | E38: Theodoros 126 / Theodoros Dalassenos, doux of Thessalonike | G38: J 1062 - J 1063 | K38: 60972463 / Papaioannou, Stratis | N38: Psellos Papaioannou 35 | O38: p. 81
A39: Psellos, Letter 36 | B39: Psellos Papaioannou 36 | C39: Michael 61 / Michael Psellos (named Konstantinos till tonsure in 1054) | E39: Theodoros 126 / Theodoros Dalassenos, doux of Thessalonike | G39: J 1062 - J 1063 | K39: 60972463 / Papaioannou, Stratis | N39: Psellos Papaioannou 36 | O39: p. 82
A40: Psellos, Letter 37 | B40: Psellos Papaioannou 37 | C40: Michael 61 / Michael Psellos (named Konstantinos till tonsure in 1054) | E40: Romanos 4 / Emperor Romanos IV Diogenes | G40: J 1069 | K40: 60972463 / Papaioannou, Stratis | N40: Psellos Papaioannou 37 | O40: p. 83
A41: Psellos, Letter 38 | B41: Psellos Papaioannou 38 | C41: Michael 61 / Michael Psellos (named Konstantinos till tonsure in 1054) | E41: Romanos 4 / Emperor Romanos IV Diogenes | G41: J 1069 | K41: 60972463 / Papaioannou, Stratis | N41: Psellos Papaioannou 38 | O41: p. 85
A42: Psellos, Letter 39 | B42: Psellos Papaioannou 39 | C42: Michael 61 / Michael Psellos (named Konstantinos till tonsure in 1054) | E42: Romanos 4 / Emperor Romanos IV Diogenes | G42: J 1072, June 29 [TPQ] | K42: 60972463 / Papaioannou, Stratis | N42: Psellos Papaioannou 39 | O42: p. 88
...

Sheet Manuscripts
A1: Identifier | B1: Dating | C1: Place copied | D1: Contains text | E1: Scribe | F1: Commissioned by | G1: Authority | H1: Authority group | I1: Based on | J1: Source text/publication | K1: Source text/reference | L1: Source text/excerpt

Sheet Historical text sources
A1: Text identifier | B1: Used source | C1: Authority | D1: Authority group | E1: Based on | F1: Source text/publication | G1: Source text/reference | H1: Source text/excerpt

Sheet Births and deaths
A1: Who | B1: Which | C1: When | D1: Where | E1: Authority | F1: Authority group | G1: Based on | H1: Source text/publication | I1: Source text/reference | J1: Source text/excerpt
A2: Anna 62 / Anna Komnene, daughter of Alexios I and historian | B2: Birth | C2: J 1083 December 2 | D2: Constantinople | E2: Anna 62 / Anna Komnene, daughter of Alexios I and historian
A3: T1 Dawatanos / Diabatenos / Dawatanos, doux of Edessa | B3: Death | C3: A 511 | D3: Amida | E3: T2 Mattheos / Matthew of Edessa | H3: Chronicle of Matthew | I3: II.17
A4: Ioannes 62 / Ioannes Doukas, kaisar | B4: Birth | D4: Paphlagonia | E4: Michael 61 / Michael Psellos (named Konstantinos till tonsure in 1054) | H4: Psellos Papaioannou 68 | I4: p. 154, l. 38
A5: Basileios 2 / Emperor Basileios II Boulgaroktonos | B5: Death | C5: J 1025 | E5: 54236315 / Pertz, Georg Heinrich | H5: Annales Barenses | I5: 39-42
A6: Abu Usama 101 / Abu Usama, the cadi of Aleppo | B6: Death | C6: J 1025 | E6: 79063594 / Yaḥyā ibn Saʻīd al-Anṭākī | H6: Yahya al-Antaki | I6: 478
A7: Mawsuf 101 / Mawsuf the eunuch | B7: Death | C7: J 1025 | E7: 79063594 / Yaḥyā ibn Saʻīd al-Anṭākī | H7: Yahya al-Antaki | I7: 478
A8: Basileios 2 / Emperor Basileios II Boulgaroktonos | B8: Death | C8: J 1025, December | E8: 256344105 / Lampsidēs, Odysseus | H8: Manasses, Chronicle | I8: 5939
A9: Basileios 2 / Emperor Basileios II Boulgaroktonos | B9: Death | C9: J 1025, December 1 | E9: 14789545 / Schreiner, Peter | H9: Kleinchroniken 15 | I9: 158,5
A10: Basileios 2 / Emperor Basileios II Boulgaroktonos | B10: Death | C10: J 1025, December 12 | E10: 79063594 / Yaḥyā ibn Saʻīd al-Anṭākī | H10: Yahya al-Antaki | I10: 480
A11: Basileios 2 / Emperor Basileios II Boulgaroktonos | B11: Death | C11: J 1025, December 13 | E11: 14789545 / Schreiner, Peter | H11: Kleinchroniken 16 | I11: 165,8
A12: Basileios 2 / Emperor Basileios II Boulgaroktonos | B12: Death | C12: J 1026 | E12: 13129565 / Anonymus Barensis | H12: Anonymus Barensis | I12: 149
A13: Georgios 105 / Georgios/Giorgi I, king of Abchasia and Georgia | B13: Death | C13: J 1027, August | E13: 54176097 / Wortley, John | H13: Skylitzes (English) | I13: p. 356, n. 18
A14: Konstantinos 8 / Emperor Konstantinos VIII | B14: Death | C14: J 1028 | E14: 0009-0007-1432-0127 / Anđelović, Aleksandar | H14: Psellos: Chronographia | I14: II 10.26-8
A15: Konstantinos 8 / Emperor Konstantinos VIII | B15: Death | C15: J 1028, November 11 | E15: 14789545 / Schreiner, Peter | H15: Kleinchroniken 15 | I15: 158,7
A16: Konstantinos 8 / Emperor Konstantinos VIII | B16: Death | C16: J 1028, November 12 | E16: 79063594 / Yaḥyā ibn Saʻīd al-Anṭākī | H16: Yahya al-Antaki | I16: 488
... A22: Helena 102 / Helena, first wife of Romanos III | B22: Death | C22: J 1032 | E22: Ioannes 110 / Ioannes Skylitzes, historian | H22: Skylitzes | I22: 386.74-78
A23: Ioannes 273 / Ioannes, John VIII bar Abdun, Jacobite patriarch of Antioch | B23: Death | C23: J 1033 | F23: Kračkovskij, Ignati; Micheau, Françoise; Troupeau, Gérard | H23: Yahya al-Antaki | I23: 490
A24: Elias 103 / Elias II, patriarch of Antioch | B24: Death | C24: J 1033, September 8 | F24: Kračkovskij, Ignati; Micheau, Françoise; Troupeau, Gérard | H24: Yahya al-Antaki | I24: 520
A25: Anonymus 153 / Varangian who attempted to rape a woman in Thrakesion | B25: Death | C25: J 1034 | E25: 0009-0007-1432-0127 / Anđelović, Aleksandar | H25: Glykas | I25: 587.1-6
A26: Anonymus 153 / Varangian who attempted to rape a woman in Thrakesion | B26: Death | C26: J 1034 | E26: 0009-0007-1432-0127 / Anđelović, Aleksandar | H26: Skylitzes | I26: 394.73-77
A27: Romanos 3 / Emperor Romanos III Argyros | B27: Death | C27: J 1034 | E27: 13129565 / Anonymus Barensis | H27: Anonymus Barensis | I27: 149
A28: Romanos 3 / Emperor Romanos III Argyros | B28: Death | C28: J 1034 | E28: 84485715 / Lupus Protospatharius | H28: Lupus protospatharius | I28: 58.4-5
A29: Romanos 3 / Emperor Romanos III Argyros | B29: Death | C29: J 1034, April 11 | E29: 0009-0007-1432-0127 / Anđelović, Aleksandar | H29: Skylitzes | I29: 388.17-18
A30: Romanos 3 / Emperor Romanos III Argyros | B30: Death | C30: J 1034, April 11 | E30: 0009-0007-1432-0127 / Anđelović, Aleksandar | H30: Skylitzes | I30: 417,92
A31: Romanos 3 / Emperor Romanos III Argyros | B31: Death | C31: J 1034, April 11 | E31: 256344105 / Lampsidēs, Odysseus | H31: Manasses, Chronicle | I31: 5992-5995
A32: Romanos 3 / Emperor Romanos III Argyros | B32: Death | C32: J 1034, April 11 | E32: Ioannes 110 / Ioannes Skylitzes, historian | H32: Skylitzes | I32: 390.93-94
A33: Romanos 3 / Emperor Romanos III Argyros | B33: Death | C33: J 1034, April 11 | E33: Ioannes 110 / Ioannes Skylitzes, historian | H33: Skylitzes | I33: 392.10-12
A34: Romanos 3 / Emperor Romanos III Argyros | B34: Death | C34: J 1034, April 11 | E34: 79063594 / Yaḥyā ibn Saʻīd al-Anṭākī | H34: Yahya al-Antaki | I34: 536
A35: Romanos 3 / Emperor Romanos III Argyros | B35: Death | C35: J 1034, April 11-12 | E35: 0009-0007-1432-0127 / Anđelović, Aleksandar | H35: Psellos: Chronographia | I35: III 26.9-12
A36: Niketas 104 / Niketas, brother of Michael IV | B36: Death | C36: J 1034, September | E36: Ioannes 110 / Ioannes Skylitzes, historian | H36: Skylitzes | I36: 397.58-60
... A48: Michael 4 / Emperor Michael IV Paphlagon | B48: Death | C48: J 1041 | E48: 13129565 / Anonymus Barensis | H48: Anonymus Barensis | I48: 150
A49: Michael 4 / Emperor Michael IV Paphlagon | B49: Death | C49: J 1041, December 10 | F49: Kaldellis, Anthony; Krallis, Dimitris | H49: Attaleiates: History (English) | I49: p. 595, n. 15
A50: Michael 4 / Emperor Michael IV Paphlagon | B50: Death | C50: J 1041, December 10 | E50: Ioannes 110 / Ioannes Skylitzes, historian | H50: Skylitzes | I50: 415.50-52
A51: Michael 4 / Emperor Michael IV Paphlagon | B51: Death | C51: J 1041, December 9-10 | E51: 14789545 / Schreiner, Peter | H51: Kleinchroniken 15 | I51: 159,9
A52: Konstantinos 112 / Konstantinos Artoklines, katepano | B52: Death | C52: J 1042 | E52: 0009-0007-1432-0127 / Anđelović, Aleksandar | H52: Skylitzes | I52: 423.31-32
A53: Konstantinos 112 / Konstantinos Artoklines, katepano | B53: Death | C53: J 1042 | E53: Michael 305 / Michael Sikidites, punished as a magician | H53: Glykas | I53: 593.5-6
A54: Michael 4 / Emperor Michael IV Paphlagon | B54: Death | C54: J 1042 | E54: 84485715 / Lupus Protospatharius | H54: Lupus protospatharius | I54: 58.20-21
A55: Apolaphar Mouchoumet 101 / Ahmad al-Akhal, amir of Sicily | B55: Death | C55: J 1042, April | E55: 54176097 / Wortley, John | H55: Skylitzes (English) | I55: p. 383
A56: Anonymus 178 / Pardos, successor of Maniakes in Italy | B56: Death | C56: J 1042, October | E56: 54176097 / Wortley, John | H56: Skylitzes (English) | I56: p. 402, n. 31
...

Sheet Relationship types
A1: Relationship type | B1: Kinship?
A2: ancestor (grandfather) | B2: yes
A3: aunt | B3: yes
A4: betrothed of granddaughter | B4: no
A5: brother | B5: yes
A6: brother (elder) | B6: yes
A7: brother (first) | B7: yes
A8: brother (full) | B8: yes
A9: brother (in fact, nephew) | B9: yes
A10: brother (in fact, uncle) | B10: yes
A11: brother (younger) | B11: yes
A12: brother-in-law | B12: yes
... A38: father-in-law (designate) | B38: no
A39: father-in-law (joint)
A40: father-in-law (potential) | B40: no
A41: father-in-law of child | B41: yes
A42: fiancé | B42: no
A43: fiancée | B43: no
A44: grand nephew | B44: yes
A45: granddaughter | B45: yes
A46: grandfather | B46: yes
A47: grandfather (maternal) | B47: yes
A48: grandfather (paternal) | B48: yes
A49: grandmother | B49: yes
A50: grandmother (maternal) | B50: yes
A51: grandmother (paternal) | B51: yes
... A151: wife (second) | B151: yes

Sheet Social relationships
A1: Main person | B1: Related person | C1: Relationship type | D1: Start date | E1: End date | F1: Authority | G1: Authority group | H1: Based on | I1: Source text/publication | J1: Source text/reference | K1: Source text/excerpt

Sheet Journeys
A1: Journey id | B1: Who travelled | C1: Group travelled | D1: Journey type | E1: Sent by person | F1: Visited person | G1: Visited place | H1: Visited when | I1: Des. Origin | J1: Des. Destination | K1: Real Origin | L1: Real Dest. | M1: Start date | N1: End date | O1: Authority | P1: Authority group | Q1: Based on | R1: Source text/publication | S1: Source text/reference | T1: Source text/excerpt

Sheet Geopolitical Events
A1: Event label | B1: Event date | C1: Event type | D1: Involved person | E1: Created place | F1: Destroyed place | G1: Challenge to authority status | H1: Intended target place of attack | I1: Intended target population | J1: Combatant individual | K1: Combatant group | L1: Authority | M1: Authority group | N1: Based on | O1: Source text/publication | P1: Source text/reference | Q1: Source text/excerpt

Sheet Authority Status
A1: Authority status label | B1: Status type | C1: Authority ascribed by | D1: Authority ascribed | E1: Geographic scope | F1: Temporal scope | G1: Authority | H1: Authority group | I1: Based on | J1: Source text/publication | K1: Source text/reference | L1: Source text/excerpt

Sheet Boulloteria
A1: Boulloterion title | B1: External URL | C1: Owner | D1: Text obverse | E1: Transl. obverse | F1: Text reverse | G1: Transl. reverse | H1: Dating | I1: Material | J1: Diameter | K1: Authority | L1: Authority group | M1: Based on | N1: Source text/publication | O1: Source text/reference | P1: Source text/excerpt

Sheet Lead seals
A1: Seal ID | B1: Seal collection | C1: Boulloterion | D1: External url

Sheet Other objects
A1: Title | B1: External identifier | C1: Description | D1: Type | E1: Documented location | F1: Documented date | G1: Creation location | H1: Creation date | I1: Decoration material | J1: Design element | K1: Material | L1: Owned by | M1: Owned by group | N1: Owned when | O1: Owned where | P1: Authority | Q1: Authority group | R1: Based on | S1: Source text/publication | T1: Source text/reference | U1: Source text/excerpt

